Workbook

Sheet Tổng quan
A1: THIẾT KẾ KHO DỮ LIỆU FORMULA 1 (F1_DWH) – PHƯƠNG PHÁP KIMBALL
A2: Dimensional Modeling Workbook · Nguồn: Formula 1 World Championship 1950–2024 (14 file CSV)
A4: Mục | B4: Nội dung
A5: Phương pháp | B5: Kimball – Bottom-up, mô hình chiều (dimensional modeling), kiến trúc bus với các chiều dùng chung (conformed dimensions).
A6: Kiến trúc | B6: 14 file CSV → F1_SOURCE (CSDL nguồn OLTP, file 00) → ETL T-SQL (schema etl, file 03) → F1_DWH (presentation area, file 01).
A7: Quy trình thiết kế 4 bước | B7: (1) Chọn quy trình nghiệp vụ → (2) Khai báo hạt (grain) → (3) Xác định chiều → (4) Xác định độ đo. Xem sheet '1. Quy trình 4 bước'.
A8: Lược đồ | B8: Chòm sao (fact constellation): 8 chiều dùng chung + 7 bảng sự kiện thuộc 7 quy trình.
A9: Loại bảng sự kiện | B9: Transaction (4 bảng), Periodic snapshot (2 bảng), Accumulating snapshot (1 bảng).
A10: Khoá thay thế | B10: Mọi chiều dùng surrogate key IDENTITY (trừ DimDate dùng khoá yyyymmdd). Khoá tự nhiên được giữ làm cột NK/durable key.
A11: Unknown member | B11: Mỗi chiều có dòng khoá -1 'Unknown'. ETL không tra được khoá → gán -1, fact không bao giờ NULL khoá ngoại.
A12: SCD | B12: Type 1 (ghi đè) cho Circuit, Race, Status; Type 1 + Type 2 (lưu lịch sử) cho Driver, Constructor. Xem sheet '4. SCD'.
A13: Kỹ thuật đặc biệt | B13: Role-playing (DimDate 4 vai, DimDriver 3 vai trong FactRaceWeekend) · Degenerate dimension (ResultID, QualifyID, StopNumber) · Audit dimension (DimAudit) · Point-in-time lookup cho SCD2 · Nạp tăng dần.
A14: Quy ước độ đo | B14: Cờ 0/1 lưu dạng TINYINT tên …Count để SUM = số lần, AVG = tỉ lệ. Thời gian lưu mili-giây (…Ms).
A15: Thứ tự chạy script | B15: 00_create_f1_source.sql → 01_create_f1_dwh.sql → 03_etl_f1_dwh.sql → 02_olap_queries.sql → 04_demo_scd2.sql
A18: Danh mục sheet
A19: Sheet | B19: Nội dung
A20: 1. Quy trình 4 bước | B20: 4 bước thiết kế Kimball cho từng quy trình nghiệp vụ
A21: 2. Bus Matrix | B21: Ma trận bus: quy trình × chiều dùng chung
A22: 3. Danh mục bảng | B22: Toàn bộ bảng chiều / sự kiện, hạt, SCD, số dòng
A23: 4. SCD | B23: Chính sách SCD cho từng thuộc tính chiều
A24: 5. Độ đo | B24: Danh sách độ đo và tính cộng dồn
A25: 6. Phân cấp | B25: Các phân cấp (hierarchy) để roll-up / drill-down
A26: DimDate | B26: Đặc tả chi tiết + ánh xạ nguồn → đích
A27: DimCircuit | B27: Đặc tả chi tiết + ánh xạ nguồn → đích
A28: DimRace | B28: Đặc tả chi tiết + ánh xạ nguồn → đích
A29: DimDriver | B29: Đặc tả chi tiết + ánh xạ nguồn → đích
A30: DimConstructor | B30: Đặc tả chi tiết + ánh xạ nguồn → đích
... A40: FactRaceWeekend | B40: Đặc tả chi tiết + ánh xạ nguồn → đích

Sheet 1. Quy trình 4 bước
A1: QUY TRÌNH THIẾT KẾ 4 BƯỚC CỦA KIMBALL
A2: Bước 1: quy trình nghiệp vụ · Bước 2: hạt · Bước 3: chiều · Bước 4: độ đo
A4: # | B4: B1. Quy trình nghiệp vụ | C4: Bảng sự kiện | D4: Loại bảng sự kiện | E4: B2. Hạt (grain) | F4: B3. Các chiều | G4: B4. Độ đo (facts) | H4: Câu hỏi phân tích
A5: 1 | B5: Kết quả đua | C5: FactRaceResult | D5: Transaction | E5: 1 tay đua × 1 phiên đua (GP/Sprint) | F5: DimDate, DimRace, DimCircuit, DimDriver, DimConstructor, DimStatus, DimSessionType, DimAudit | G5: Points, Grid/Finish position, RaceTimeMs, FastestLap*, PositionsGained, Win/Podium/Pole/DNF/HomeRace Count | H5: Ai thắng nhiều nhất? Tỉ lệ DNF theo thời kỳ? Lợi thế sân nhà?
A6: 2 | B6: Phân hạng | C6: FactQualifying | D6: Transaction | E6: 1 tay đua × 1 chặng | F6: DimDate, DimRace, DimCircuit, DimDriver, DimConstructor, DimAudit | G6: QualiPosition, Q1/Q2/Q3Ms, BestLapMs, GapToPole, ReachedQ2/Q3 | H6: Đội nào nhanh nhất ở phân hạng?
A7: 3 | B7: Tính giờ vòng đua | C7: FactLapTime | D7: Transaction | E7: 1 tay đua × 1 vòng × 1 chặng | F7: DimDate, DimRace, DimCircuit, DimDriver, DimConstructor, DimAudit | G7: LapTimeMs, PositionOnLap | H7: Vòng nhanh nhất mỗi trường đua? Tốc độ thay đổi theo năm?
A8: 4 | B8: Pit stop | C8: FactPitStop | D8: Transaction | E8: 1 lần vào pit | F8: DimDate, DimRace, DimCircuit, DimDriver, DimConstructor, DimAudit | G8: PitLaneTimeMs, LapNumber, OutlierCount | H8: Đội nào pit nhanh nhất mỗi mùa?
A9: 5 | B9: Xếp hạng vô địch – tay đua | C9: FactDriverStandingSnapshot | D9: Periodic snapshot | E9: 1 tay đua × sau mỗi chặng | F9: DimDate, DimRace, DimDriver, DimAudit | G9: StandingPosition, CumulativePoints, CumulativeWins (semi-additive) | H9: Ai vô địch? Cuộc đua điểm diễn biến ra sao?
A10: 6 | B10: Xếp hạng vô địch – đội | C10: FactConstructorStandingSnapshot | D10: Periodic snapshot | E10: 1 đội × sau mỗi chặng | F10: DimDate, DimRace, DimConstructor, DimAudit | G10: StandingPosition, CumulativePoints, CumulativeWins (semi-additive) | H10: Đội nào vô địch từng mùa?
A11: 7 | B11: Cuối tuần đua | C11: FactRaceWeekend | D11: Accumulating snapshot | E11: 1 chặng đua (cập nhật theo mốc) | F11: DimDate, DimRace, DimCircuit, DimDriver, DimConstructor, DimAudit | G11: Entrant/Classified/DNF Count, WinningMarginMs, PoleLapMs, PitStopCount, DaysFP1ToRace, PoleConvertedCount | H11: Tỉ lệ pole → thắng? Cách biệt chiến thắng?

Sheet 2. Bus Matrix
A1: MA TRẬN BUS (ENTERPRISE DATA WAREHOUSE BUS MATRIX)
A2: X = quy trình dùng chiều đó · 'X (n vai)' = role-playing · Chiều dùng chung (conformed) giúp khoan ngang (drill-across) giữa các bảng sự kiện
A4: Quy trình nghiệp vụ | B4: Bảng sự kiện | C4: DimDate | D4: DimRace | E4: DimCircuit | F4: DimDriver | G4: DimConstructor | H4: DimStatus | I4: DimSessionType | J4: DimAudit | K4: Số chiều
A5: Kết quả đua | B5: FactRaceResult | C5: X | D5: X | E5: X | F5: X | G5: X | H5: X | I5: X | J5: X | K5: =COUNTIF(C5:J5,"X*") -> 8
A6: Phân hạng | B6: FactQualifying | C6: X | D6: X | E6: X | F6: X | G6: X | J6: X | K6: =COUNTIF(C6:J6,"X*") -> 6
A7: Tính giờ vòng đua | B7: FactLapTime | C7: X | D7: X | E7: X | F7: X | G7: X | J7: X | K7: =COUNTIF(C7:J7,"X*") -> 6
A8: Pit stop | B8: FactPitStop | C8: X | D8: X | E8: X | F8: X | G8: X | J8: X | K8: =COUNTIF(C8:J8,"X*") -> 6
A9: Xếp hạng vô địch – tay đua | B9: FactDriverStandingSnapshot | C9: X | D9: X | F9: X | J9: X | K9: =COUNTIF(C9:J9,"X*") -> 4
A10: Xếp hạng vô địch – đội | B10: FactConstructorStandingSnapshot | C10: X | D10: X | G10: X | J10: X | K10: =COUNTIF(C10:J10,"X*") -> 4
A11: Cuối tuần đua | B11: FactRaceWeekend | C11: X (4 vai) | D11: X | E11: X | F11: X (3 vai) | G11: X | J11: X | K11: =COUNTIF(C11:J11,"X*") -> 6
A12: Số quy trình dùng chiều | C12: =COUNTIF(C5:C11,"X*") -> 7 | D12: =COUNTIF(D5:D11,"X*") -> 7 | E12: =COUNTIF(E5:E11,"X*") -> 5 | F12: =COUNTIF(F5:F11,"X*") -> 6 | G12: =COUNTIF(G5:G11,"X*") -> 6 | H12: =COUNTIF(H5:H11,"X*") -> 1 | I12: =COUNTIF(I5:I11,"X*") -> 1 | J12: =COUNTIF(J5:J11,"X*") -> 7 | K12: =SUM(K5:K11) -> 40
A14: Ghi chú: DimAudit là audit dimension – gắn với mọi bảng sự kiện để truy vết lô ETL.

Sheet 3. Danh mục bảng
A1: DANH MỤC BẢNG TRONG F1_DWH
A2: Số cột được đếm bằng công thức từ sheet đặc tả của từng bảng
A4: Bảng | B4: Loại | C4: Loại fact | D4: Hạt (grain) | E4: Xử lý thay đổi / nạp | F4: Số dòng (sau lần nạp đầu) | G4: Số cột | H4: Mô tả
A5: DimDate | B5: Chiều | C5: — | D5: 1 dòng = 1 ngày dương lịch (1950-01-01 → 2030-12-31) + 1 dòng Unknown | E5: Tĩnh (sinh sẵn) | F5: 29,586 | G5: =COUNTA(DimDate!A8:A18) -> 11 | H5: Chiều ngày dùng chung; nhập vai (role-playing) trong FactRaceWeekend (FP1, Quali, Sprint, Race).
A6: DimCircuit | B6: Chiều | C6: — | D6: 1 dòng = 1 trường đua | E6: Type 1 | F6: 78 | G6: =COUNTA(DimCircuit!A8:A19) -> 12 | H6: Trường đua; phân cấp Continent → Country → City → Circuit.
A7: DimRace | B7: Chiều | C7: — | D7: 1 dòng = 1 chặng đua | E7: Type 1 | F7: 1,126 | G7: =COUNTA(DimRace!A8:A20) -> 13 | H7: Chặng đua (Grand Prix); phân cấp Decade → Season → Round.
A8: DimDriver | B8: Chiều | C8: — | D8: 1 dòng = 1 phiên bản của 1 tay đua | E8: Type 1 + Type 2 | F8: 862 (ban đầu) | G8: =COUNTA(DimDriver!A8:A23) -> 16 | H8: Tay đua. SCD hỗn hợp: Type 2 cho mã, số xe, quốc tịch; Type 1 cho tên, ngày sinh.
A9: DimConstructor | B9: Chiều | C9: — | D9: 1 dòng = 1 phiên bản của 1 đội | E9: Type 1 + Type 2 | F9: 213 (ban đầu) | G9: =COUNTA(DimConstructor!A8:A17) -> 10 | H9: Đội đua. Type 2 cho tên đội và quốc tịch; Type 1 cho mã tham chiếu.
A10: DimStatus | B10: Chiều | C10: — | D10: 1 dòng = 1 trạng thái | E10: Type 1 | F10: 140 | G10: =COUNTA(DimStatus!A8:A14) -> 7 | H10: Trạng thái kết thúc cuộc đua; phân cấp StatusGroup → Status.
A11: DimSessionType | B11: Chiều | C11: — | D11: 1 dòng = 1 loại phiên | E11: Tĩnh | F11: 3 | G11: =COUNTA(DimSessionType!A8:A10) -> 3 | H11: Loại phiên đua, cho phép gộp Grand Prix và Sprint trong 1 fact.
A12: DimAudit | B12: Chiều | C12: — | D12: 1 dòng = 1 lô ETL | E12: Chỉ thêm (append) | F12: Tăng theo số lần chạy | G12: =COUNTA(DimAudit!A8:A15) -> 8 | H12: Audit dimension (Kimball ETL subsystem): mỗi lần chạy ETL = 1 dòng; mọi fact mang AuditKey.
A13: FactRaceResult | B13: Fact | C13: Transaction | D13: 1 dòng = 1 tay đua × 1 phiên đua | E13: Nạp tăng dần | F13: 27,119 | G13: =COUNTA(FactRaceResult!A8:A36) -> 29 | H13: Kết quả của mỗi tay đua trong mỗi phiên đua (Grand Prix + Sprint).
A14: FactQualifying | B14: Fact | C14: Transaction | D14: 1 dòng = 1 tay đua × 1 chặng | E14: Nạp tăng dần | F14: 10,494 | G14: =COUNTA(FactQualifying!A8:A24) -> 17 | H14: Kết quả phân hạng (từ 1994).
A15: FactLapTime | B15: Fact | C15: Transaction | D15: 1 dòng = 1 tay đua × 1 vòng × 1 chặng | E15: Nạp tăng dần | F15: 589,081 | G15: =COUNTA(FactLapTime!A8:A16) -> 9 | H15: Thời gian từng vòng đua (từ 1996) – bảng lớn nhất.
A16: FactPitStop | B16: Fact | C16: Transaction | D16: 1 dòng = 1 lần vào pit | E16: Nạp tăng dần | F16: 11,371 | G16: =COUNTA(FactPitStop!A8:A18) -> 11 | H16: Mỗi lần vào pit (từ 2011).
A17: FactDriverStandingSnapshot | B17: Fact | C17: Periodic snapshot | D17: 1 dòng = 1 tay đua × sau 1 chặng | E17: Nạp tăng dần | F17: 34,863 | G17: =COUNTA(FactDriverStandingSnapshot!A8:A14) -> 7 | H17: Bảng xếp hạng tay đua sau mỗi chặng.
A18: FactConstructorStandingSnapshot | B18: Fact | C18: Periodic snapshot | D18: 1 dòng = 1 đội × sau 1 chặng | E18: Nạp tăng dần | F18: 13,391 | G18: =COUNTA(FactConstructorStandingSnapshot!A8:A14) -> 7 | H18: Bảng xếp hạng đội đua sau mỗi chặng (từ 1958).
A19: FactRaceWeekend | B19: Fact | C19: Accumulating snapshot | D19: 1 dòng = 1 chặng đua | E19: MERGE (insert + update) | F19: 1,125 | G19: =COUNTA(FactRaceWeekend!A8:A28) -> 21 | H19: Tiến trình cuối tuần đua: một dòng được CẬP NHẬT khi các mốc FP1 → Quali → Sprint → Race hoàn thành. Minh hoạ role-playing.
A20: Tổng | G20: =SUM(G5:G19) -> 181

Sheet 4. SCD
A1: CHÍNH SÁCH SCD (SLOWLY CHANGING DIMENSIONS)
A2: Type 1 = ghi đè (không giữ lịch sử) · Type 2 = đóng dòng cũ, thêm dòng mới với RowEffectiveDate / RowExpirationDate / IsCurrentRow
A4: Chiều | B4: Thuộc tính | C4: SCD Type | D4: Lý do | E4: Cách ETL xử lý
A5: DimCircuit | B5: CircuitRef | C5: Type 1 | D5: Sửa lỗi / thông tin mô tả – báo cáo luôn dùng giá trị mới nhất | E5: UPDATE mọi dòng cùng khoá tự nhiên (MERGE … WHEN MATCHED)
A6: DimCircuit | B6: CircuitName | C6: Type 1 | D6: Sửa lỗi / thông tin mô tả – báo cáo luôn dùng giá trị mới nhất | E6: UPDATE mọi dòng cùng khoá tự nhiên (MERGE … WHEN MATCHED)
A7: DimCircuit | B7: City | C7: Type 1 | D7: Sửa lỗi / thông tin mô tả – báo cáo luôn dùng giá trị mới nhất | E7: UPDATE mọi dòng cùng khoá tự nhiên (MERGE … WHEN MATCHED)
A8: DimCircuit | B8: Country | C8: Type 1 | D8: Sửa lỗi / thông tin mô tả – báo cáo luôn dùng giá trị mới nhất | E8: UPDATE mọi dòng cùng khoá tự nhiên (MERGE … WHEN MATCHED)
A9: DimCircuit | B9: Continent | C9: Type 1 | D9: Sửa lỗi / thông tin mô tả – báo cáo luôn dùng giá trị mới nhất | E9: UPDATE mọi dòng cùng khoá tự nhiên (MERGE … WHEN MATCHED)
A10: DimCircuit | B10: Latitude | C10: Type 1 | D10: Sửa lỗi / thông tin mô tả – báo cáo luôn dùng giá trị mới nhất | E10: UPDATE mọi dòng cùng khoá tự nhiên (MERGE … WHEN MATCHED)
A11: DimCircuit | B11: Longitude | C11: Type 1 | D11: Sửa lỗi / thông tin mô tả – báo cáo luôn dùng giá trị mới nhất | E11: UPDATE mọi dòng cùng khoá tự nhiên (MERGE … WHEN MATCHED)
A12: DimCircuit | B12: AltitudeM | C12: Type 1 | D12: Sửa lỗi / thông tin mô tả – báo cáo luôn dùng giá trị mới nhất | E12: UPDATE mọi dòng cùng khoá tự nhiên (MERGE … WHEN MATCHED)
A13: DimRace | B13: RaceName | C13: Type 1 | D13: Sửa lỗi / thông tin mô tả – báo cáo luôn dùng giá trị mới nhất | E13: UPDATE mọi dòng cùng khoá tự nhiên (MERGE … WHEN MATCHED)
A14: DimRace | B14: Season | C14: Type 1 | D14: Sửa lỗi / thông tin mô tả – báo cáo luôn dùng giá trị mới nhất | E14: UPDATE mọi dòng cùng khoá tự nhiên (MERGE … WHEN MATCHED)
A15: DimRace | B15: Decade | C15: Type 1 | D15: Sửa lỗi / thông tin mô tả – báo cáo luôn dùng giá trị mới nhất | E15: UPDATE mọi dòng cùng khoá tự nhiên (MERGE … WHEN MATCHED)
... A36: DimStatus | B36: FinishClassification | C36: Type 1 | D36: Sửa lỗi / thông tin mô tả – báo cáo luôn dùng giá trị mới nhất | E36: UPDATE mọi dòng cùng khoá tự nhiên (MERGE … WHEN MATCHED)
A38: Tổng thuộc tính Type 2 | C38: =COUNTIF(C5:C36,"Type 2") -> 6
A39: Tổng thuộc tính Type 1 | C39: =COUNTIF(C5:C36,"Type 1") -> 26

Sheet 5. Độ đo
A1: DANH SÁCH ĐỘ ĐO (MEASURES)
A2: Additive: cộng theo mọi chiều · Semi-additive: không cộng theo thời gian · Non-additive: dùng MIN/MAX/AVG
A4: Bảng sự kiện | B4: Độ đo | C4: Kiểu | D4: Tính cộng dồn | E4: Mô tả | F4: Quy tắc tính
A5: FactRaceResult | B5: GridPosition | C5: INT | D5: Non-additive | E5: Vị trí xuất phát (0 = pit lane)
A6: FactRaceResult | B6: FinishPosition | C6: INT | D6: Non-additive | E6: Vị trí về đích (NULL = không xếp hạng) | F6: '\N' → NULL
A7: FactRaceResult | B7: PositionOrder | C7: INT | D7: Non-additive | E7: Thứ tự xếp hạng cuối
A8: FactRaceResult | B8: Points | C8: DECIMAL(6,2) | D8: Additive | E8: Điểm giành được
A9: FactRaceResult | B9: LapsCompleted | C9: INT | D9: Additive | E9: Số vòng hoàn thành
A10: FactRaceResult | B10: RaceTimeMs | C10: BIGINT | D10: Non-additive | E10: Tổng thời gian đua (ms)
A11: FactRaceResult | B11: FastestLapNumber | C11: INT | D11: Non-additive | E11: Vòng chạy nhanh nhất
A12: FactRaceResult | B12: FastestLapRank | C12: INT | D12: Non-additive | E12: Hạng vòng nhanh nhất
A13: FactRaceResult | B13: FastestLapTimeMs | C13: INT | D13: Non-additive | E13: Thời gian vòng nhanh nhất (ms) | F13: etl.fn_TimeToMs('m:ss.fff')
A14: FactRaceResult | B14: FastestLapSpeedKph | C14: DECIMAL(7,3) | D14: Non-additive | E14: Tốc độ vòng nhanh nhất (km/h)
A15: FactRaceResult | B15: DriverAgeAtRace | C15: DECIMAL(4,1) | D15: Non-additive | E15: Tuổi tay đua tại ngày đua | F15: DATEDIFF(DAY,dob,RaceDate)/365.25
A16: FactRaceResult | B16: PositionsGained | C16: INT | D16: Additive | E16: Số bậc tăng | F16: grid > 0 → grid − positionOrder
A17: FactRaceResult | B17: WinCount | C17: TINYINT | D17: Additive | E17: 1 nếu thắng | F17: position = 1
A18: FactRaceResult | B18: PodiumCount | C18: TINYINT | D18: Additive | E18: 1 nếu lên bục | F18: position ≤ 3
A19: FactRaceResult | B19: PoleCount | C19: TINYINT | D19: Additive | E19: 1 nếu xuất phát đầu | F19: grid = 1
A20: FactRaceResult | B20: PointsFinishCount | C20: TINYINT | D20: Additive | E20: 1 nếu có điểm | F20: points > 0
A21: FactRaceResult | B21: DNFCount | C21: TINYINT | D21: Additive | E21: 1 nếu không được xếp hạng | F21: FinishClassification ≠ 'Classified'
A22: FactRaceResult | B22: HomeRaceCount | C22: TINYINT | D22: Additive | E22: 1 nếu đua trên sân nhà | F22: NationalityCountry = Country
A23: FactQualifying | B23: QualiPosition | C23: INT | D23: Non-additive | E23: Vị trí phân hạng
A24: FactQualifying | B24: Q1Ms | C24: INT | D24: Non-additive | E24: Thời gian Q1 (ms) | F24: etl.fn_TimeToMs
A25: FactQualifying | B25: Q2Ms | C25: INT | D25: Non-additive | E25: Thời gian Q2 (ms) | F25: etl.fn_TimeToMs
A26: FactQualifying | B26: Q3Ms | C26: INT | D26: Non-additive | E26: Thời gian Q3 (ms) | F26: etl.fn_TimeToMs
A27: FactQualifying | B27: BestLapMs | C27: INT | D27: Non-additive | E27: Vòng tốt nhất trong Q1–Q3 | F27: MIN của 3 phiên
A28: FactQualifying | B28: GapToPoleMs | C28: INT | D28: Non-additive | E28: Cách pole (ms) | F28: BestLapMs − MIN(BestLapMs) trong chặng
A29: FactQualifying | B29: GapToPolePct | C29: DECIMAL(7,3) | D29: Non-additive | E29: Cách pole (%) | F29: GapToPoleMs / PoleMs × 100
A30: FactQualifying | B30: ReachedQ2Count | C30: TINYINT | D30: Additive | E30: 1 nếu vào Q2 | F30: q2 IS NOT NULL
A31: FactQualifying | B31: ReachedQ3Count | C31: TINYINT | D31: Additive | E31: 1 nếu vào Q3 | F31: q3 IS NOT NULL
A32: FactLapTime | B32: PositionOnLap | C32: INT | D32: Non-additive | E32: Vị trí sau vòng
A33: FactLapTime | B33: LapTimeMs | C33: INT | D33: Non-additive | E33: Thời gian vòng (ms)
A34: FactPitStop | B34: LapNumber | C34: INT | D34: Non-additive | E34: Vòng vào pit
A35: FactPitStop | B35: PitLaneTimeMs | C35: INT | D35: Non-additive | E35: Thời gian đi qua pit lane (ms)
A36: FactPitStop | B36: OutlierCount | C36: TINYINT | D36: Additive | E36: 1 nếu > 60 giây (cờ đỏ, sửa xe) | F36: milliseconds > 60000
A37: FactDriverStandingSnapshot | B37: StandingPosition | C37: INT | D37: Non-additive | E37: Hạng hiện tại
A38: FactDriverStandingSnapshot | B38: CumulativePoints | C38: DECIMAL(6,2) | D38: Semi-additive | E38: Điểm luỹ kế – KHÔNG cộng theo thời gian
A39: FactDriverStandingSnapshot | B39: CumulativeWins | C39: INT | D39: Semi-additive | E39: Số trận thắng luỹ kế
A40: FactConstructorStandingSnapshot | B40: StandingPosition | C40: INT | D40: Non-additive | E40: Hạng hiện tại
A41: FactConstructorStandingSnapshot | B41: CumulativePoints | C41: DECIMAL(6,2) | D41: Semi-additive | E41: Điểm luỹ kế
...

Sheet 6. Phân cấp
A1: PHÂN CẤP (HIERARCHIES) CHO ROLL-UP / DRILL-DOWN
A4: Chiều | B4: Phân cấp (từ tổng quát → chi tiết) | C4: Ví dụ
A5: DimDate | B5: Decade → Year → Quarter → Month → Day | C5: 2020s → 2024 → Q1 → March → 2
A6: DimRace | B6: Decade → Season → Round (Race) | C6: 2020s → 2024 → Round 1 Bahrain GP
A7: DimCircuit | B7: Continent → Country → City → Circuit | C7: Oceania → Australia → Melbourne → Albert Park
A8: DimStatus | B8: FinishClassification → StatusGroup → Status | C8: Not classified → Mechanical / Technical → Engine
A9: DimDriver | B9: NationalityCountry → Nationality → Driver | C9: UK → British → Lewis Hamilton
A10: DimConstructor | B10: Nationality → Constructor | C10: British → McLaren

Sheet DimDate
A1: DimDate
A2: Chiều ngày dùng chung; nhập vai (role-playing) trong FactRaceWeekend (FP1, Quali, Sprint, Race).
A3: Loại bảng | B3: Chiều
A4: Hạt (grain) | B4: 1 dòng = 1 ngày dương lịch (1950-01-01 → 2030-12-31) + 1 dòng Unknown
A5: Xử lý thay đổi / nạp | B5: Tĩnh (sinh sẵn)
A7: Cột | B7: Kiểu dữ liệu | C7: Loại khoá / vai trò | D7: SCD / Cộng dồn | E7: Null? | F7: Mô tả | G7: Nguồn (F1_SOURCE) | H7: Quy tắc ETL | I7: Ví dụ
A8: DateKey | B8: INT | C8: PK (smart key) | D8: — | E8: N | F8: Khoá yyyymmdd; -1 = Unknown | G8: Sinh tự động | H8: YEAR*10000+MONTH*100+DAY | I8: 20240302
A9: FullDate | B9: DATE | D9: — | E9: N | F9: Ngày đầy đủ | G9: Sinh tự động | I9: 2024-03-02
A10: Day | B10: TINYINT | D10: — | E10: N | F10: Ngày trong tháng | G10: Sinh tự động | H10: DAY(FullDate) | I10: 2
A11: Month | B11: TINYINT | D11: — | E11: N | F11: Tháng | G11: Sinh tự động | H11: MONTH(FullDate) | I11: 3
A12: MonthName | B12: NVARCHAR(10) | D12: — | E12: N | F12: Tên tháng | G12: Sinh tự động | H12: DATENAME(MONTH) | I12: March
A13: Quarter | B13: TINYINT | D13: — | E13: N | F13: Quý | G13: Sinh tự động | H13: DATEPART(QUARTER) | I13: 1
A14: Year | B14: SMALLINT | D14: — | E14: N | F14: Năm | G14: Sinh tự động | H14: YEAR(FullDate) | I14: 2024
A15: Decade | B15: NVARCHAR(7) | D15: — | E15: N | F15: Thập kỷ | G15: Sinh tự động | H15: YEAR/10*10 + 's' | I15: 2020s
A16: DayOfWeek | B16: TINYINT | D16: — | E16: N | F16: Thứ trong tuần (1 = Thứ Hai) | G16: Sinh tự động | H16: DATEDIFF(DAY,'19000101',d)%7+1 | I16: 6
A17: DayName | B17: NVARCHAR(10) | D17: — | E17: N | F17: Tên thứ | G17: Sinh tự động | H17: DATENAME(WEEKDAY) | I17: Saturday
A18: WeekdayWeekend | B18: NVARCHAR(7) | D18: — | E18: N | F18: Ngày thường / cuối tuần | G18: Sinh tự động | H18: Thứ 7, CN → 'Weekend' | I18: Weekend
A20: ← Về danh mục bảng

Sheet DimCircuit
A1: DimCircuit
A2: Trường đua; phân cấp Continent → Country → City → Circuit.
A3: Loại bảng | B3: Chiều
A4: Hạt (grain) | B4: 1 dòng = 1 trường đua
A5: Xử lý thay đổi / nạp | B5: Type 1
A7: Cột | B7: Kiểu dữ liệu | C7: Loại khoá / vai trò | D7: SCD / Cộng dồn | E7: Null? | F7: Mô tả | G7: Nguồn (F1_SOURCE) | H7: Quy tắc ETL | I7: Ví dụ
A8: CircuitKey | B8: INT IDENTITY | C8: PK (surrogate) | D8: — | E8: N | F8: Khoá thay thế; -1 = Unknown | G8: ETL sinh | H8: IDENTITY | I8: 1
A9: CircuitID | B9: INT | C9: NK (natural key) | D9: — | E9: N | F9: Khoá tự nhiên từ nguồn | G9: F1_SOURCE.dbo.circuits.circuitId | I9: 1
A10: CircuitRef | B10: NVARCHAR(50) | D10: 1 | E10: N | F10: Mã tham chiếu | G10: F1_SOURCE.dbo.circuits.circuitRef | I10: albert_park
A11: CircuitName | B11: NVARCHAR(100) | D11: 1 | E11: N | F11: Tên trường đua | G11: F1_SOURCE.dbo.circuits.name | I11: Albert Park Grand Prix Circuit
A12: City | B12: NVARCHAR(100) | D12: 1 | E12: N | F12: Thành phố | G12: F1_SOURCE.dbo.circuits.location | H12: NULL → 'Unknown' | I12: Melbourne
A13: Country | B13: NVARCHAR(50) | D13: 1 | E13: N | F13: Quốc gia | G13: F1_SOURCE.dbo.circuits.country | H13: 'United States' → 'USA' | I13: Australia
A14: Continent | B14: NVARCHAR(20) | D14: 1 | E14: N | F14: Châu lục (làm giàu) | G14: etl.MapCountryContinent | H14: Không có trong bảng tra → 'Europe' | I14: Oceania
A15: Latitude | B15: DECIMAL(9,5) | D15: 1 | E15: Y | F15: Vĩ độ | G15: F1_SOURCE.dbo.circuits.lat | I15: -37.84970
A16: Longitude | B16: DECIMAL(9,5) | D16: 1 | E16: Y | F16: Kinh độ | G16: F1_SOURCE.dbo.circuits.lng | I16: 144.96800
A17: AltitudeM | B17: INT | D17: 1 | E17: Y | F17: Độ cao (m) | G17: F1_SOURCE.dbo.circuits.alt | I17: 10
A18: RowInsertedAt | B18: DATETIME2(0) | C18: Audit | D18: — | E18: N | F18: Thời điểm thêm dòng | G18: ETL | H18: SYSDATETIME()
A19: RowUpdatedAt | B19: DATETIME2(0) | C19: Audit | D19: — | E19: N | F19: Thời điểm cập nhật gần nhất | G19: ETL | H19: SYSDATETIME()
A21: ← Về danh mục bảng

Sheet DimRace
A1: DimRace
A2: Chặng đua (Grand Prix); phân cấp Decade → Season → Round.
A3: Loại bảng | B3: Chiều
A4: Hạt (grain) | B4: 1 dòng = 1 chặng đua
A5: Xử lý thay đổi / nạp | B5: Type 1
A7: Cột | B7: Kiểu dữ liệu | C7: Loại khoá / vai trò | D7: SCD / Cộng dồn | E7: Null? | F7: Mô tả | G7: Nguồn (F1_SOURCE) | H7: Quy tắc ETL | I7: Ví dụ
A8: RaceKey | B8: INT IDENTITY | C8: PK (surrogate) | D8: — | E8: N | F8: Khoá thay thế; -1 = Unknown | G8: ETL sinh | H8: IDENTITY | I8: 1
A9: RaceID | B9: INT | C9: NK | D9: — | E9: N | F9: Khoá tự nhiên | G9: F1_SOURCE.dbo.races.raceId | I9: 1121
A10: RaceName | B10: NVARCHAR(100) | D10: 1 | E10: N | F10: Tên chặng | G10: F1_SOURCE.dbo.races.name | I10: Bahrain Grand Prix
A11: Season | B11: SMALLINT | D11: 1 | E11: N | F11: Mùa giải | G11: F1_SOURCE.dbo.races.year | I11: 2024
A12: Decade | B12: NVARCHAR(7) | D12: 1 | E12: N | F12: Thập kỷ | G12: F1_SOURCE.dbo.races.year | H12: year/10*10 + 's' | I12: 2020s
A13: Round | B13: TINYINT | D13: 1 | E13: N | F13: Vòng thứ mấy trong mùa | G13: F1_SOURCE.dbo.races.round | I13: 1
A14: RoundsInSeason | B14: TINYINT | D14: 1 | E14: N | F14: Tổng số vòng của mùa (dẫn xuất) | G14: F1_SOURCE.dbo.races | H14: MAX(round) OVER (PARTITION BY year) | I14: 24
A15: IsSeasonFinale | B15: NVARCHAR(3) | D15: 1 | E15: N | F15: Chặng cuối mùa? (dẫn xuất) | G15: F1_SOURCE.dbo.races | H15: round = RoundsInSeason → 'Yes' | I15: No
A16: RaceDate | B16: DATE | D16: 1 | E16: Y | F16: Ngày đua | G16: F1_SOURCE.dbo.races.date | I16: 2024-03-02
A17: RaceStartTimeUTC | B17: TIME(0) | D17: 1 | E17: Y | F17: Giờ xuất phát (UTC) | G17: F1_SOURCE.dbo.races.time | I17: 15:00:00
A18: WeekendFormat | B18: NVARCHAR(20) | D18: 1 | E18: N | F18: Thể thức cuối tuần (dẫn xuất) | G18: F1_SOURCE.dbo.races + sprint_results | H18: Có sprint → 'Sprint' ngược lại 'Standard' | I18: Standard
A19: RowInsertedAt | B19: DATETIME2(0) | C19: Audit | D19: — | E19: N | F19: Thời điểm thêm dòng | G19: ETL
A20: RowUpdatedAt | B20: DATETIME2(0) | C20: Audit | D20: — | E20: N | F20: Thời điểm cập nhật gần nhất | G20: ETL
A22: ← Về danh mục bảng

Sheet DimDriver
A1: DimDriver
A2: Tay đua. SCD hỗn hợp: Type 2 cho mã, số xe, quốc tịch; Type 1 cho tên, ngày sinh.
A3: Loại bảng | B3: Chiều
A4: Hạt (grain) | B4: 1 dòng = 1 phiên bản của 1 tay đua
A5: Xử lý thay đổi / nạp | B5: Type 1 + Type 2
A7: Cột | B7: Kiểu dữ liệu | C7: Loại khoá / vai trò | D7: SCD / Cộng dồn | E7: Null? | F7: Mô tả | G7: Nguồn (F1_SOURCE) | H7: Quy tắc ETL | I7: Ví dụ
A8: DriverKey | B8: INT IDENTITY | C8: PK (surrogate) | D8: — | E8: N | F8: Khoá thay thế – mỗi phiên bản 1 khoá; -1 = Unknown | G8: ETL sinh | H8: IDENTITY | I8: 1
A9: DriverID | B9: INT | C9: NK / Durable key | D9: — | E9: N | F9: Khoá bền, không đổi qua các phiên bản | G9: F1_SOURCE.dbo.drivers.driverId | I9: 1
A10: DriverRef | B10: NVARCHAR(50) | D10: 1 | E10: N | F10: Mã tham chiếu | G10: F1_SOURCE.dbo.drivers.driverRef | I10: hamilton
A11: DriverCode | B11: NVARCHAR(3) | D11: 2 | E11: N | F11: Mã 3 ký tự | G11: F1_SOURCE.dbo.drivers.code | H11: NULL → 'N/A' | I11: HAM
A12: PermanentNumber | B12: NVARCHAR(3) | D12: 2 | E12: N | F12: Số xe cố định | G12: F1_SOURCE.dbo.drivers.number | H12: NULL → 'N/A' | I12: 44
A13: FirstName | B13: NVARCHAR(50) | D13: 1 | E13: N | F13: Tên | G13: F1_SOURCE.dbo.drivers.forename | I13: Lewis
A14: LastName | B14: NVARCHAR(50) | D14: 1 | E14: N | F14: Họ | G14: F1_SOURCE.dbo.drivers.surname | I14: Hamilton
A15: FullName | B15: NVARCHAR(101) | D15: 1 | E15: N | F15: Họ tên đầy đủ (dẫn xuất) | G15: F1_SOURCE.dbo.drivers | H15: forename + ' ' + surname | I15: Lewis Hamilton
A16: DateOfBirth | B16: DATE | D16: 1 | E16: Y | F16: Ngày sinh | G16: F1_SOURCE.dbo.drivers.dob | I16: 1985-01-07
A17: Nationality | B17: NVARCHAR(50) | D17: 2 | E17: N | F17: Quốc tịch | G17: F1_SOURCE.dbo.drivers.nationality | H17: LTRIM/RTRIM | I17: British
A18: NationalityCountry | B18: NVARCHAR(50) | D18: 2 | E18: N | F18: Quốc gia của quốc tịch (làm giàu) | G18: etl.MapNationalityCountry | H18: Dùng tính HomeRaceCount | I18: UK
A19: RowEffectiveDate | B19: DATE | C19: SCD2 | D19: — | E19: N | F19: Ngày bắt đầu hiệu lực | G19: ETL | H19: Dòng đầu tiên: 1900-01-01; phiên bản mới: ngày chạy ETL | I19: 1900-01-01
A20: RowExpirationDate | B20: DATE | C20: SCD2 | D20: — | E20: N | F20: Ngày hết hiệu lực | G20: ETL | H20: Dòng hiện hành: 9999-12-31 | I20: 9999-12-31
A21: IsCurrentRow | B21: NVARCHAR(7) | C21: SCD2 | D21: — | E21: N | F21: Dòng hiện hành? | G21: ETL | H21: 'Current' / 'Expired' | I21: Current
A22: RowInsertedAt | B22: DATETIME2(0) | C22: Audit | D22: — | E22: N | F22: Thời điểm thêm dòng | G22: ETL
A23: RowUpdatedAt | B23: DATETIME2(0) | C23: Audit | D23: — | E23: N | F23: Thời điểm cập nhật gần nhất | G23: ETL
A25: ← Về danh mục bảng

Sheet DimConstructor
A1: DimConstructor
A2: Đội đua. Type 2 cho tên đội và quốc tịch; Type 1 cho mã tham chiếu.
A3: Loại bảng | B3: Chiều
A4: Hạt (grain) | B4: 1 dòng = 1 phiên bản của 1 đội
A5: Xử lý thay đổi / nạp | B5: Type 1 + Type 2
A7: Cột | B7: Kiểu dữ liệu | C7: Loại khoá / vai trò | D7: SCD / Cộng dồn | E7: Null? | F7: Mô tả | G7: Nguồn (F1_SOURCE) | H7: Quy tắc ETL | I7: Ví dụ
A8: ConstructorKey | B8: INT IDENTITY | C8: PK (surrogate) | D8: — | E8: N | F8: Khoá thay thế; -1 = Unknown | G8: ETL sinh | H8: IDENTITY | I8: 1
A9: ConstructorID | B9: INT | C9: NK / Durable key | D9: — | E9: N | F9: Khoá bền | G9: F1_SOURCE.dbo.constructors.constructorId | I9: 1
A10: ConstructorRef | B10: NVARCHAR(50) | D10: 1 | E10: N | F10: Mã tham chiếu | G10: F1_SOURCE.dbo.constructors.constructorRef | I10: mclaren
A11: ConstructorName | B11: NVARCHAR(100) | D11: 2 | E11: N | F11: Tên đội | G11: F1_SOURCE.dbo.constructors.name | I11: McLaren
A12: Nationality | B12: NVARCHAR(50) | D12: 2 | E12: N | F12: Quốc tịch đội | G12: F1_SOURCE.dbo.constructors.nationality | H12: LTRIM/RTRIM | I12: British
A13: RowEffectiveDate | B13: DATE | C13: SCD2 | D13: — | E13: N | F13: Ngày bắt đầu hiệu lực | G13: ETL | I13: 1900-01-01
A14: RowExpirationDate | B14: DATE | C14: SCD2 | D14: — | E14: N | F14: Ngày hết hiệu lực | G14: ETL | I14: 9999-12-31
A15: IsCurrentRow | B15: NVARCHAR(7) | C15: SCD2 | D15: — | E15: N | F15: Dòng hiện hành? | G15: ETL | I15: Current
A16: RowInsertedAt | B16: DATETIME2(0) | C16: Audit | D16: — | E16: N | G16: ETL
A17: RowUpdatedAt | B17: DATETIME2(0) | C17: Audit | D17: — | E17: N | G17: ETL
A19: ← Về danh mục bảng

Sheet DimStatus
A1: DimStatus
A2: Trạng thái kết thúc cuộc đua; phân cấp StatusGroup → Status.
A3: Loại bảng | B3: Chiều
A4: Hạt (grain) | B4: 1 dòng = 1 trạng thái
A5: Xử lý thay đổi / nạp | B5: Type 1
A7: Cột | B7: Kiểu dữ liệu | C7: Loại khoá / vai trò | D7: SCD / Cộng dồn | E7: Null? | F7: Mô tả | G7: Nguồn (F1_SOURCE) | H7: Quy tắc ETL | I7: Ví dụ
A8: StatusKey | B8: INT IDENTITY | C8: PK (surrogate) | D8: — | E8: N | F8: Khoá thay thế; -1 = Unknown | G8: ETL sinh | H8: IDENTITY | I8: 1
A9: StatusID | B9: INT | C9: NK | D9: — | E9: N | F9: Khoá tự nhiên | G9: F1_SOURCE.dbo.status.statusId | I9: 1
A10: StatusDesc | B10: NVARCHAR(50) | D10: 1 | E10: N | F10: Mô tả trạng thái | G10: F1_SOURCE.dbo.status.status | I10: Finished
A11: StatusGroup | B11: NVARCHAR(40) | D11: 1 | E11: N | F11: Nhóm trạng thái (8 nhóm, dẫn xuất) | G11: F1_SOURCE.dbo.status.status | H11: CASE theo từ khoá (Engine → Mechanical…) | I11: Finished
A12: FinishClassification | B12: NVARCHAR(20) | D12: 1 | E12: N | F12: Được xếp hạng hoàn thành? | G12: StatusGroup | H12: Finished / Finished (lapped) → 'Classified' | I12: Classified
A13: RowInsertedAt | B13: DATETIME2(0) | C13: Audit | D13: — | E13: N | G13: ETL
A14: RowUpdatedAt | B14: DATETIME2(0) | C14: Audit | D14: — | E14: N | G14: ETL
A16: ← Về danh mục bảng

Sheet DimSessionType
A1: DimSessionType
A2: Loại phiên đua, cho phép gộp Grand Prix và Sprint trong 1 fact.
A3: Loại bảng | B3: Chiều
A4: Hạt (grain) | B4: 1 dòng = 1 loại phiên
A5: Xử lý thay đổi / nạp | B5: Tĩnh
A7: Cột | B7: Kiểu dữ liệu | C7: Loại khoá / vai trò | D7: SCD / Cộng dồn | E7: Null? | F7: Mô tả | G7: Nguồn (F1_SOURCE) | H7: Quy tắc ETL | I7: Ví dụ
A8: SessionTypeKey | B8: INT | C8: PK | D8: — | E8: N | F8: 1 = Grand Prix, 2 = Sprint, -1 = Unknown | G8: Nạp tay (DDL) | I8: 1
A9: SessionType | B9: NVARCHAR(20) | D9: — | E9: N | F9: Tên loại phiên | G9: Nạp tay | I9: Grand Prix
A10: PointsSystem | B10: NVARCHAR(50) | D10: — | E10: N | F10: Mô tả hệ thống điểm | G10: Nạp tay | I10: Full points (25-18-15-...)
A12: ← Về danh mục bảng

Sheet DimAudit
A1: DimAudit
A2: Audit dimension (Kimball ETL subsystem): mỗi lần chạy ETL = 1 dòng; mọi fact mang AuditKey.
A3: Loại bảng | B3: Chiều
A4: Hạt (grain) | B4: 1 dòng = 1 lô ETL
A5: Xử lý thay đổi / nạp | B5: Chỉ thêm (append)
A7: Cột | B7: Kiểu dữ liệu | C7: Loại khoá / vai trò | D7: SCD / Cộng dồn | E7: Null? | F7: Mô tả | G7: Nguồn (F1_SOURCE) | H7: Quy tắc ETL | I7: Ví dụ
A8: AuditKey | B8: INT IDENTITY | C8: PK (surrogate) | D8: — | E8: N | F8: Khoá lô ETL; -1 = Unknown | G8: ETL sinh | H8: IDENTITY | I8: 1
A9: EtlBatchName | B9: NVARCHAR(100) | D9: — | E9: N | F9: Tên lô | G9: etl.usp_Run_ETL | I9: F1 incremental load
A10: SourceSystem | B10: NVARCHAR(50) | D10: — | E10: N | F10: Hệ thống nguồn | G10: etl.usp_Run_ETL | I10: F1_SOURCE
A11: BatchStartTime | B11: DATETIME2(0) | D11: — | E11: N | F11: Bắt đầu | G11: etl.usp_Run_ETL
A12: BatchEndTime | B12: DATETIME2(0) | D12: — | E12: Y | F12: Kết thúc | G12: etl.usp_Run_ETL
A13: BatchStatus | B13: NVARCHAR(20) | D13: — | E13: N | F13: Running / Succeeded / Failed | G13: etl.usp_Run_ETL | I13: Succeeded
A14: RowsInserted | B14: INT | D14: — | E14: Y | F14: Tổng dòng fact thêm/cập nhật | G14: etl.usp_Run_ETL | I14: 686319
A15: ErrorMessage | B15: NVARCHAR(4000) | D15: — | E15: Y | F15: Thông báo lỗi nếu thất bại | G15: etl.usp_Run_ETL | H15: ERROR_MESSAGE()
A17: ← Về danh mục bảng

Sheet FactRaceResult
A1: FactRaceResult
A2: Kết quả của mỗi tay đua trong mỗi phiên đua (Grand Prix + Sprint).
A3: Loại bảng | B3: Fact – Transaction
A4: Hạt (grain) | B4: 1 dòng = 1 tay đua × 1 phiên đua
A5: Xử lý thay đổi / nạp | B5: Nạp tăng dần
A7: Cột | B7: Kiểu dữ liệu | C7: Loại khoá / vai trò | D7: SCD / Cộng dồn | E7: Null? | F7: Mô tả | G7: Nguồn (F1_SOURCE) | H7: Quy tắc ETL | I7: Ví dụ
A8: RaceResultKey | B8: BIGINT IDENTITY | C8: PK (surrogate) | D8: — | E8: N | F8: Khoá dòng fact | G8: ETL sinh | H8: IDENTITY
A9: RaceDateKey | B9: INT | C9: FK → DimDate | D9: — | E9: N | F9: Ngày đua | G9: Tra khoá thay thế | H9: Không thấy → -1
A10: RaceKey | B10: INT | C10: FK → DimRace | D10: — | E10: N | F10: Khoá ngoại tới DimRace | G10: Tra khoá thay thế | H10: Không thấy → -1
A11: CircuitKey | B11: INT | C11: FK → DimCircuit | D11: — | E11: N | F11: Khoá ngoại tới DimCircuit | G11: Tra khoá thay thế | H11: Không thấy → -1
A12: DriverKey | B12: INT | C12: FK → DimDriver | D12: — | E12: N | F12: Tay đua (phiên bản đúng tại ngày đua) | G12: results.driverId | H12: Point-in-time: RaceDate BETWEEN RowEffectiveDate AND RowExpirationDate
A13: ConstructorKey | B13: INT | C13: FK → DimConstructor | D13: — | E13: N | F13: Đội đua (point-in-time) | G13: results.constructorId | H13: Point-in-time lookup
A14: StatusKey | B14: INT | C14: FK → DimStatus | D14: — | E14: N | F14: Khoá ngoại tới DimStatus | G14: Tra khoá thay thế | H14: Không thấy → -1
A15: SessionTypeKey | B15: INT | C15: FK → DimSessionType | D15: — | E15: N | F15: 1 = results, 2 = sprint_results | G15: Tra khoá thay thế | H15: Không thấy → -1
A16: AuditKey | B16: INT | C16: FK → DimAudit | D16: — | E16: N | F16: Lô ETL đã nạp dòng | G16: Tra khoá thay thế | H16: Không thấy → -1
A17: ResultID | B17: INT | C17: DD (degenerate) | D17: — | E17: N | F17: Mã kết quả nguồn | G17: results.resultId / sprint_results.resultId | H17: UNIQUE(SessionTypeKey, ResultID) – dùng kiểm tra trùng khi nạp tăng dần | I17: 1
A18: CarNumber | B18: INT | C18: DD | D18: — | E18: Y | F18: Số xe trong chặng | G18: results.number
A19: GridPosition | B19: INT | C19: Measure | D19: Non-additive | E19: Y | F19: Vị trí xuất phát (0 = pit lane) | G19: results.grid | I19: 1
A20: FinishPosition | B20: INT | C20: Measure | D20: Non-additive | E20: Y | F20: Vị trí về đích (NULL = không xếp hạng) | G20: results.position | H20: '\N' → NULL | I20: 1
A21: PositionOrder | B21: INT | C21: Measure | D21: Non-additive | E21: N | F21: Thứ tự xếp hạng cuối | G21: results.positionOrder | I21: 1
A22: Points | B22: DECIMAL(6,2) | C22: Measure | D22: Additive | E22: N | F22: Điểm giành được | G22: results.points | I22: 25.00
A23: LapsCompleted | B23: INT | C23: Measure | D23: Additive | E23: N | F23: Số vòng hoàn thành | G23: results.laps | I23: 57
A24: RaceTimeMs | B24: BIGINT | C24: Measure | D24: Non-additive | E24: Y | F24: Tổng thời gian đua (ms) | G24: results.milliseconds
A25: FastestLapNumber | B25: INT | C25: Measure | D25: Non-additive | E25: Y | F25: Vòng chạy nhanh nhất | G25: results.fastestLap
A26: FastestLapRank | B26: INT | C26: Measure | D26: Non-additive | E26: Y | F26: Hạng vòng nhanh nhất | G26: results.rank
A27: FastestLapTimeMs | B27: INT | C27: Measure | D27: Non-additive | E27: Y | F27: Thời gian vòng nhanh nhất (ms) | G27: results.fastestLapTime | H27: etl.fn_TimeToMs('m:ss.fff') | I27: 92608
A28: FastestLapSpeedKph | B28: DECIMAL(7,3) | C28: Measure | D28: Non-additive | E28: Y | F28: Tốc độ vòng nhanh nhất (km/h) | G28: results.fastestLapSpeed
A29: DriverAgeAtRace | B29: DECIMAL(4,1) | C29: Measure | D29: Non-additive | E29: Y | F29: Tuổi tay đua tại ngày đua | G29: drivers.dob + races.date | H29: DATEDIFF(DAY,dob,RaceDate)/365.25 | I29: 39.2
A30: PositionsGained | B30: INT | C30: Measure | D30: Additive | E30: Y | F30: Số bậc tăng | G30: grid, positionOrder | H30: grid > 0 → grid − positionOrder | I30: 3
A31: WinCount | B31: TINYINT | C31: Measure (indicator) | D31: Additive | E31: N | F31: 1 nếu thắng | G31: results.position | H31: position = 1 | I31: 1
A32: PodiumCount | B32: TINYINT | C32: Measure (indicator) | D32: Additive | E32: N | F32: 1 nếu lên bục | G32: results.position | H32: position ≤ 3 | I32: 1
A33: PoleCount | B33: TINYINT | C33: Measure (indicator) | D33: Additive | E33: N | F33: 1 nếu xuất phát đầu | G33: results.grid | H33: grid = 1 | I33: 1
A34: PointsFinishCount | B34: TINYINT | C34: Measure (indicator) | D34: Additive | E34: N | F34: 1 nếu có điểm | G34: results.points | H34: points > 0 | I34: 1
A35: DNFCount | B35: TINYINT | C35: Measure (indicator) | D35: Additive | E35: N | F35: 1 nếu không được xếp hạng | G35: DimStatus | H35: FinishClassification ≠ 'Classified' | I35: 0
A36: HomeRaceCount | B36: TINYINT | C36: Measure (indicator) | D36: Additive | E36: N | F36: 1 nếu đua trên sân nhà | G36: DimDriver, DimCircuit | H36: NationalityCountry = Country | I36: 0
A38: ← Về danh mục bảng

Sheet FactQualifying
A1: FactQualifying
A2: Kết quả phân hạng (từ 1994).
A3: Loại bảng | B3: Fact – Transaction
A4: Hạt (grain) | B4: 1 dòng = 1 tay đua × 1 chặng
A5: Xử lý thay đổi / nạp | B5: Nạp tăng dần
A7: Cột | B7: Kiểu dữ liệu | C7: Loại khoá / vai trò | D7: SCD / Cộng dồn | E7: Null? | F7: Mô tả | G7: Nguồn (F1_SOURCE) | H7: Quy tắc ETL | I7: Ví dụ
A8: QualifyingKey | B8: BIGINT IDENTITY | C8: PK (surrogate) | D8: — | E8: N | F8: Khoá dòng fact | G8: ETL sinh
A9: RaceDateKey | B9: INT | C9: FK → DimDate | D9: — | E9: N | F9: Khoá ngoại tới DimDate | G9: Tra khoá thay thế | H9: Không thấy → -1
A10: RaceKey | B10: INT | C10: FK → DimRace | D10: — | E10: N | F10: Khoá ngoại tới DimRace | G10: Tra khoá thay thế | H10: Không thấy → -1
A11: CircuitKey | B11: INT | C11: FK → DimCircuit | D11: — | E11: N | F11: Khoá ngoại tới DimCircuit | G11: Tra khoá thay thế | H11: Không thấy → -1
A12: DriverKey | B12: INT | C12: FK → DimDriver | D12: — | E12: N | F12: Point-in-time lookup | G12: Tra khoá thay thế | H12: Không thấy → -1
A13: ConstructorKey | B13: INT | C13: FK → DimConstructor | D13: — | E13: N | F13: Point-in-time lookup | G13: Tra khoá thay thế | H13: Không thấy → -1
A14: AuditKey | B14: INT | C14: FK → DimAudit | D14: — | E14: N | F14: Khoá ngoại tới DimAudit | G14: Tra khoá thay thế | H14: Không thấy → -1
A15: QualifyID | B15: INT | C15: DD | D15: — | E15: N | F15: Mã phân hạng nguồn (UNIQUE) | G15: qualifying.qualifyId
A16: QualiPosition | B16: INT | C16: Measure | D16: Non-additive | E16: N | F16: Vị trí phân hạng | G16: qualifying.position | I16: 1
A17: Q1Ms | B17: INT | C17: Measure | D17: Non-additive | E17: Y | F17: Thời gian Q1 (ms) | G17: qualifying.q1 | H17: etl.fn_TimeToMs | I17: 89708
A18: Q2Ms | B18: INT | C18: Measure | D18: Non-additive | E18: Y | F18: Thời gian Q2 (ms) | G18: qualifying.q2 | H18: etl.fn_TimeToMs
A19: Q3Ms | B19: INT | C19: Measure | D19: Non-additive | E19: Y | F19: Thời gian Q3 (ms) | G19: qualifying.q3 | H19: etl.fn_TimeToMs
A20: BestLapMs | B20: INT | C20: Measure | D20: Non-additive | E20: Y | F20: Vòng tốt nhất trong Q1–Q3 | G20: Q1Ms, Q2Ms, Q3Ms | H20: MIN của 3 phiên
A21: GapToPoleMs | B21: INT | C21: Measure | D21: Non-additive | E21: Y | F21: Cách pole (ms) | G21: BestLapMs | H21: BestLapMs − MIN(BestLapMs) trong chặng
A22: GapToPolePct | B22: DECIMAL(7,3) | C22: Measure | D22: Non-additive | E22: Y | F22: Cách pole (%) | G22: BestLapMs | H22: GapToPoleMs / PoleMs × 100
A23: ReachedQ2Count | B23: TINYINT | C23: Measure (indicator) | D23: Additive | E23: N | F23: 1 nếu vào Q2 | G23: q2 | H23: q2 IS NOT NULL
A24: ReachedQ3Count | B24: TINYINT | C24: Measure (indicator) | D24: Additive | E24: N | F24: 1 nếu vào Q3 | G24: q3 | H24: q3 IS NOT NULL
A26: ← Về danh mục bảng

Sheet FactLapTime
A1: FactLapTime
A2: Thời gian từng vòng đua (từ 1996) – bảng lớn nhất.
A3: Loại bảng | B3: Fact – Transaction
A4: Hạt (grain) | B4: 1 dòng = 1 tay đua × 1 vòng × 1 chặng
A5: Xử lý thay đổi / nạp | B5: Nạp tăng dần
A7: Cột | B7: Kiểu dữ liệu | C7: Loại khoá / vai trò | D7: SCD / Cộng dồn | E7: Null? | F7: Mô tả | G7: Nguồn (F1_SOURCE) | H7: Quy tắc ETL | I7: Ví dụ
A8: RaceDateKey | B8: INT | C8: FK → DimDate | D8: — | E8: N | F8: Khoá ngoại tới DimDate | G8: Tra khoá thay thế | H8: Không thấy → -1
A9: RaceKey | B9: INT | C9: PK, FK → DimRace | D9: — | E9: N | F9: Chặng | G9: lap_times.raceId | H9: Tra khoá
A10: CircuitKey | B10: INT | C10: FK → DimCircuit | D10: — | E10: N | F10: Khoá ngoại tới DimCircuit | G10: Tra khoá thay thế | H10: Không thấy → -1
A11: DriverKey | B11: INT | C11: PK, FK → DimDriver | D11: — | E11: N | F11: Tay đua (point-in-time) | G11: lap_times.driverId | H11: Tra khoá
A12: ConstructorKey | B12: INT | C12: FK → DimConstructor | D12: — | E12: N | F12: Đội đua – không có trong nguồn | G12: results (raceId, driverId) | H12: Tra đội từ results theo cặp chặng + tay đua
A13: AuditKey | B13: INT | C13: FK → DimAudit | D13: — | E13: N | F13: Khoá ngoại tới DimAudit | G13: Tra khoá thay thế | H13: Không thấy → -1
A14: LapNumber | B14: INT | C14: PK, DD | D14: — | E14: N | F14: Số thứ tự vòng | G14: lap_times.lap | I14: 1
A15: PositionOnLap | B15: INT | C15: Measure | D15: Non-additive | E15: Y | F15: Vị trí sau vòng | G15: lap_times.position | I15: 1
A16: LapTimeMs | B16: INT | C16: Measure | D16: Non-additive | E16: N | F16: Thời gian vòng (ms) | G16: lap_times.milliseconds | I16: 98109
A18: ← Về danh mục bảng

Sheet FactPitStop
A1: FactPitStop
A2: Mỗi lần vào pit (từ 2011).
A3: Loại bảng | B3: Fact – Transaction
A4: Hạt (grain) | B4: 1 dòng = 1 lần vào pit
A5: Xử lý thay đổi / nạp | B5: Nạp tăng dần
A7: Cột | B7: Kiểu dữ liệu | C7: Loại khoá / vai trò | D7: SCD / Cộng dồn | E7: Null? | F7: Mô tả | G7: Nguồn (F1_SOURCE) | H7: Quy tắc ETL | I7: Ví dụ
A8: RaceDateKey | B8: INT | C8: FK → DimDate | D8: — | E8: N | F8: Khoá ngoại tới DimDate | G8: Tra khoá thay thế | H8: Không thấy → -1
A9: RaceKey | B9: INT | C9: PK, FK → DimRace | D9: — | E9: N | F9: Chặng | G9: pit_stops.raceId
A10: CircuitKey | B10: INT | C10: FK → DimCircuit | D10: — | E10: N | F10: Khoá ngoại tới DimCircuit | G10: Tra khoá thay thế | H10: Không thấy → -1
A11: DriverKey | B11: INT | C11: PK, FK → DimDriver | D11: — | E11: N | F11: Tay đua | G11: pit_stops.driverId
A12: ConstructorKey | B12: INT | C12: FK → DimConstructor | D12: — | E12: N | F12: Đội đua | G12: results (raceId, driverId) | H12: Tra đội từ results
A13: AuditKey | B13: INT | C13: FK → DimAudit | D13: — | E13: N | F13: Khoá ngoại tới DimAudit | G13: Tra khoá thay thế | H13: Không thấy → -1
A14: StopNumber | B14: INT | C14: PK, DD | D14: — | E14: N | F14: Lần vào pit thứ mấy | G14: pit_stops.stop | I14: 1
A15: LapNumber | B15: INT | C15: Measure | D15: Non-additive | E15: N | F15: Vòng vào pit | G15: pit_stops.lap | I15: 14
A16: StopTimeOfDay | B16: TIME(0) | C16: Attribute | D16: — | E16: Y | F16: Giờ vào pit | G16: pit_stops.time | I16: 17:05:23
A17: PitLaneTimeMs | B17: INT | C17: Measure | D17: Non-additive | E17: Y | F17: Thời gian đi qua pit lane (ms) | G17: pit_stops.milliseconds | I17: 23606
A18: OutlierCount | B18: TINYINT | C18: Measure (indicator) | D18: Additive | E18: N | F18: 1 nếu > 60 giây (cờ đỏ, sửa xe) | G18: pit_stops.milliseconds | H18: milliseconds > 60000 | I18: 0
A20: ← Về danh mục bảng

Sheet FactDriverStandingSnapshot
A1: FactDriverStandingSnapshot
A2: Bảng xếp hạng tay đua sau mỗi chặng.
A3: Loại bảng | B3: Fact – Periodic snapshot
A4: Hạt (grain) | B4: 1 dòng = 1 tay đua × sau 1 chặng
A5: Xử lý thay đổi / nạp | B5: Nạp tăng dần
A7: Cột | B7: Kiểu dữ liệu | C7: Loại khoá / vai trò | D7: SCD / Cộng dồn | E7: Null? | F7: Mô tả | G7: Nguồn (F1_SOURCE) | H7: Quy tắc ETL | I7: Ví dụ
A8: RaceDateKey | B8: INT | C8: FK → DimDate | D8: — | E8: N | F8: Khoá ngoại tới DimDate | G8: Tra khoá thay thế | H8: Không thấy → -1
A9: RaceKey | B9: INT | C9: PK, FK → DimRace | D9: — | E9: N | F9: Chặng (thời điểm chụp) | G9: driver_standings.raceId
A10: DriverKey | B10: INT | C10: PK, FK → DimDriver | D10: — | E10: N | F10: Tay đua | G10: driver_standings.driverId
A11: AuditKey | B11: INT | C11: FK → DimAudit | D11: — | E11: N | F11: Khoá ngoại tới DimAudit | G11: Tra khoá thay thế | H11: Không thấy → -1
A12: StandingPosition | B12: INT | C12: Measure | D12: Non-additive | E12: N | F12: Hạng hiện tại | G12: driver_standings.position | I12: 1
A13: CumulativePoints | B13: DECIMAL(6,2) | C13: Measure | D13: Semi-additive | E13: N | F13: Điểm luỹ kế – KHÔNG cộng theo thời gian | G13: driver_standings.points | I13: 437.00
A14: CumulativeWins | B14: INT | C14: Measure | D14: Semi-additive | E14: N | F14: Số trận thắng luỹ kế | G14: driver_standings.wins | I14: 9
A16: ← Về danh mục bảng

Sheet FactConstructorStandingSnapshot
A1: FactConstructorStandingSnapshot
A2: Bảng xếp hạng đội đua sau mỗi chặng (từ 1958).
A3: Loại bảng | B3: Fact – Periodic snapshot
A4: Hạt (grain) | B4: 1 dòng = 1 đội × sau 1 chặng
A5: Xử lý thay đổi / nạp | B5: Nạp tăng dần
A7: Cột | B7: Kiểu dữ liệu | C7: Loại khoá / vai trò | D7: SCD / Cộng dồn | E7: Null? | F7: Mô tả | G7: Nguồn (F1_SOURCE) | H7: Quy tắc ETL | I7: Ví dụ
A8: RaceDateKey | B8: INT | C8: FK → DimDate | D8: — | E8: N | F8: Khoá ngoại tới DimDate | G8: Tra khoá thay thế | H8: Không thấy → -1
A9: RaceKey | B9: INT | C9: PK, FK → DimRace | D9: — | E9: N | F9: Chặng | G9: constructor_standings.raceId
A10: ConstructorKey | B10: INT | C10: PK, FK → DimConstructor | D10: — | E10: N | F10: Đội đua | G10: constructor_standings.constructorId
A11: AuditKey | B11: INT | C11: FK → DimAudit | D11: — | E11: N | F11: Khoá ngoại tới DimAudit | G11: Tra khoá thay thế | H11: Không thấy → -1
A12: StandingPosition | B12: INT | C12: Measure | D12: Non-additive | E12: N | F12: Hạng hiện tại | G12: constructor_standings.position | I12: 1
A13: CumulativePoints | B13: DECIMAL(6,2) | C13: Measure | D13: Semi-additive | E13: N | F13: Điểm luỹ kế | G13: constructor_standings.points | I13: 666.00
A14: CumulativeWins | B14: INT | C14: Measure | D14: Semi-additive | E14: N | F14: Số trận thắng luỹ kế | G14: constructor_standings.wins | I14: 6
A16: ← Về danh mục bảng

Sheet FactRaceWeekend
A1: FactRaceWeekend
A2: Tiến trình cuối tuần đua: một dòng được CẬP NHẬT khi các mốc FP1 → Quali → Sprint → Race hoàn thành. Minh hoạ role-playing.
A3: Loại bảng | B3: Fact – Accumulating snapshot
A4: Hạt (grain) | B4: 1 dòng = 1 chặng đua
A5: Xử lý thay đổi / nạp | B5: MERGE (insert + update)
A7: Cột | B7: Kiểu dữ liệu | C7: Loại khoá / vai trò | D7: SCD / Cộng dồn | E7: Null? | F7: Mô tả | G7: Nguồn (F1_SOURCE) | H7: Quy tắc ETL | I7: Ví dụ
A8: RaceKey | B8: INT | C8: PK, FK → DimRace | D8: — | E8: N | F8: Chặng | G8: races.raceId
A9: CircuitKey | B9: INT | C9: FK → DimCircuit | D9: — | E9: N | F9: Khoá ngoại tới DimCircuit | G9: Tra khoá thay thế | H9: Không thấy → -1
A10: FP1DateKey | B10: INT | C10: FK → DimDate (vai FP1) | D10: — | E10: N | F10: Ngày tập FP1 – role-playing | G10: races.fp1_date | H10: NULL → -1
A11: QualifyingDateKey | B11: INT | C11: FK → DimDate (vai Quali) | D11: — | E11: N | F11: Ngày phân hạng – role-playing | G11: races.quali_date | H11: NULL → -1
A12: SprintDateKey | B12: INT | C12: FK → DimDate (vai Sprint) | D12: — | E12: N | F12: Ngày sprint – role-playing | G12: races.sprint_date | H12: NULL → -1
A13: RaceDateKey | B13: INT | C13: FK → DimDate (vai Race) | D13: — | E13: N | F13: Ngày đua – role-playing | G13: races.date
A14: PoleSitterDriverKey | B14: INT | C14: FK → DimDriver (vai Pole) | D14: — | E14: N | F14: Người xuất phát đầu – role-playing | G14: FactRaceResult | H14: GridPosition = 1
A15: WinnerDriverKey | B15: INT | C15: FK → DimDriver (vai Winner) | D15: — | E15: N | F15: Người thắng – role-playing | G15: FactRaceResult | H15: FinishPosition = 1
A16: FastestLapDriverKey | B16: INT | C16: FK → DimDriver (vai Fastest lap) | D16: — | E16: N | F16: Người có vòng nhanh nhất – role-playing | G16: FactRaceResult | H16: FastestLapRank = 1
A17: WinnerConstructorKey | B17: INT | C17: FK → DimConstructor | D17: — | E17: N | F17: Đội thắng | G17: FactRaceResult
A18: AuditKey | B18: INT | C18: FK → DimAudit | D18: — | E18: N | F18: Lô ETL cập nhật gần nhất | G18: Tra khoá thay thế | H18: Không thấy → -1
A19: EntrantCount | B19: INT | C19: Measure | D19: Additive | E19: Y | F19: Số tay đua tham gia | G19: FactRaceResult | H19: COUNT(*) | I19: 20
A20: ClassifiedCount | B20: INT | C20: Measure | D20: Additive | E20: Y | F20: Số tay đua được xếp hạng | G20: FactRaceResult | H20: SUM(DNFCount = 0) | I20: 18
A21: DNFCount | B21: INT | C21: Measure | D21: Additive | E21: Y | F21: Số tay đua bỏ cuộc | G21: FactRaceResult | H21: SUM(DNFCount) | I21: 2
A22: RaceLaps | B22: INT | C22: Measure | D22: Non-additive | E22: Y | F22: Số vòng của chặng | G22: FactRaceResult | H22: MAX(LapsCompleted) | I22: 57
A23: WinnerRaceTimeMs | B23: BIGINT | C23: Measure | D23: Non-additive | E23: Y | F23: Thời gian của người thắng | G23: FactRaceResult
A24: WinningMarginMs | B24: INT | C24: Measure | D24: Non-additive | E24: Y | F24: Cách biệt P1–P2 (ms) | G24: FactRaceResult | H24: P2.RaceTimeMs − P1.RaceTimeMs
A25: PoleLapMs | B25: INT | C25: Measure | D25: Non-additive | E25: Y | F25: Vòng pole (ms) | G25: FactQualifying | H25: BestLapMs của QualiPosition = 1
A26: PitStopCount | B26: INT | C26: Measure | D26: Additive | E26: Y | F26: Tổng số lần vào pit | G26: FactPitStop | H26: COUNT(*); 0 → NULL (chưa có dữ liệu)
A27: DaysFP1ToRace | B27: INT | C27: Measure (lag) | D27: Non-additive | E27: Y | F27: Số ngày từ FP1 tới race | G27: races | H27: DATEDIFF(DAY, fp1_date, date) | I27: 2
A28: PoleConvertedCount | B28: TINYINT | C28: Measure (indicator) | D28: Additive | E28: Y | F28: 1 nếu người giành pole thắng | G28: FactRaceResult | H28: Pole = Winner
A30: ← Về danh mục bảng
